<?xml version="1.0" encoding="utf-8"?>
<!-- This URDF was automatically created by SolidWorks to URDF Exporter! Originally created by
Stephen Brawner (brawner@gmail.com) 
     Commit Version: 1.6.0-4-g7f85cfe  Build Version: 1.6.7995.38578
     For more information, please see http://wiki.ros.org/sw_urdf_exporter -->
<robot
  name="mrs_hudson">
  <link name="world" />
  <joint name="fixed" type="fixed">
    <parent link="world" />
    <child link="base_link" />
  </joint>
  <link
    name="base_link">
    <inertial>
      <origin
        xyz="0 0 0.15487131491131"
        rpy="0 0 0" />
      <mass
        value="3.6423410343121" />
      <inertia
        ixx="0.0185811851538252"
        ixy="7.57952268850217E-06"
        ixz="-4.01112281502012E-05"
        iyy="0.018703374094642"
        iyz="3.4509222598916E-09"
        izz="0.0172725195870509" />
    </inertial>
    <visual>
      <origin
        xyz="0 0 0"
        rpy="0 0 0" />
      <geometry>
        <mesh
          filename="file:///home/ubuntu/erc_ws/src/assgn/meshes/base_link.stl" />
      </geometry>
      <material
        name="">
        <color
          rgba="0.792156862745098 0.819607843137255 0.933333333333333 1" />
      </material>
    </visual>
    <collision>
      <origin
        xyz="0 0 0"
        rpy="0 0 0" />
      <geometry>
        <mesh
          filename="file:///home/ubuntu/erc_ws/src/assgn/meshes/base_link.stl" />
      </geometry>
    </collision>
  </link>
  <link name="lidar_link">
    <pose>0 0 0.49 0 0 0</pose>
    <inertial>
      <mass>0.1</mass>
      <inertia>
        <ixx>0.000166667</ixx>
        <iyy>0.000166667</iyy>
        <izz>0.000166667</izz>
      </inertia>
    </inertial>
    <collision name="collision">
      <geometry>
        <box>
          <size>0.07 0.07 0.07</size>
        </box>
      </geometry>
    </collision>
    <visual name="visual">
      <geometry>
        <box>
          <size>0.07 0.07 0.07</size>
        </box>
      </geometry>
    </visual>
    <sensor name='gpu_lidar' type='gpu_lidar'>
      <pose>0 0 0 0 0 0</pose>
      <topic>lidar</topic>
      <update_rate>10</update_rate>
      <lidar>
        <scan>
          <horizontal>
            <samples>640</samples>
            <resolution>1</resolution>
            <min_angle>-1.396263</min_angle>
            <max_angle>1.396263</max_angle>
          </horizontal>
          <vertical>
            <samples>1</samples>
            <resolution>1</resolution>
            <min_angle>0.0</min_angle>
            <max_angle>0.0</max_angle>
          </vertical>
        </scan>
        <range>
          <min>0.08</min>
          <max>10.0</max>
          <resolution>0.01</resolution>
        </range>
      </lidar>
      <alwaysOn>1</alwaysOn>
      <visualize>true</visualize>
    </sensor>
  </link>

  <link name="camera_link">
    <pose>0 0 0.57 0 0 0</pose>
    <inertial>
      <mass>0.1</mass>
      <inertia>
        <ixx>0.000166667</ixx>
        <iyy>0.000166667</iyy>
        <izz>0.000166667</izz>
      </inertia>
    </inertial>
    <collision name="collision">
      <geometry>
        <box>
          <size>0.07 0.07 0.07</size>
        </box>
      </geometry>
    </collision>
    <visual name="visual">
      <geometry>
        <box>
          <size>0.07 0.07 0.07</size>
        </box>
      </geometry>
    </visual>
    <sensor name="camera" type="camera">
      <camera>
        <horizontal_fov>1.047</horizontal_fov>
        <image>
          <width>320</width>
          <height>240</height>
        </image>
        <clip>
          <near>0.1</near>
          <far>100</far>
        </clip>
      </camera>
      <always_on>1</always_on>
      <update_rate>30</update_rate>
      <visualize>true</visualize>
      <topic>camera</topic>
    </sensor>
  </link>

  <link
    name="left_wheel">
    <inertial>
      <origin
        xyz="0 0 0"
        rpy="0 0 0" />
      <mass
        value="0.00727826709042055" />
      <inertia
        ixx="2.80246683878592E-06"
        ixy="-2.57707915048983E-10"
        ixz="-4.50883143298705E-21"
        iyy="2.8010936780627E-06"
        iyz="-1.1335430564382E-19"
        izz="4.95155146638645E-06" />
    </inertial>
    <visual>
      <origin
        xyz="0 0 0"
        rpy="0 0 0" />
      <geometry>
        <mesh
          filename="file:///home/ubuntu/erc_ws/src/assgn/meshes/left_wheel.stl" />
      </geometry>
      <material
        name="">
        <color
          rgba="0.792156862745098 0.819607843137255 0.933333333333333 1" />
      </material>
    </visual>
    <collision>
      <origin
        xyz="0 0 0"
        rpy="0 0 0" />
      <geometry>
        <mesh
          filename="file:///home/ubuntu/erc_ws/src/assgn/meshes/left_wheel.stl" />
      </geometry>
    </collision>
  </link>
  <joint
    name="left_wheel_joint"
    type="continuous">
    <parent
      link="base_link" />
    <child
      link="left_wheel" />
    <origin
      xyz="0 0.0591 0.02675"
      rpy="1.5708 0 -3.1416" />
    <axis
      xyz="0 0 -1" />
  </joint>
  <link
    name="right_wheel">
    <inertial>
      <origin
        xyz="0 0 0"
        rpy="0 0 0" />
      <mass
        value="0.00727826709042085" />
      <inertia
        ixx="2.80246683878609E-06"
        ixy="2.57707915045793E-10"
        ixz="-8.11251891134899E-22"
        iyy="2.80109367806286E-06"
        iyz="6.68884025356048E-21"
        izz="4.95155146638674E-06" />
    </inertial>
    <visual>
      <origin
        xyz="0 0 0"
        rpy="0 0 0" />
      <geometry>
        <mesh
          filename="file:///home/ubuntu/erc_ws/src/assgn/meshes/right_wheel.stl" />
      </geometry>
      <material
        name="">
        <color
          rgba="0.792156862745098 0.819607843137255 0.933333333333333 1" />
      </material>
    </visual>
    <collision>
      <origin
        xyz="0 0 0"
        rpy="0 0 0" />
      <geometry>
        <mesh
          filename="file:///home/ubuntu/erc_ws/src/assgn/meshes/right_wheel.stl" />
      </geometry>
    </collision>
  </link>
  <joint
    name="right_wheel_joint"
    type="continuous">
    <parent
      link="base_link" />
    <child
      link="right_wheel" />
    <origin
      xyz="0 -0.0591 0.02675"
      rpy="-1.5708 0 3.1416" />
    <axis
      xyz="0 0 -1" />
  </joint>
  <joint name='lidar_sensor_joint' type='fixed'>
    <parent link='base_link'/>
    <child link='lidar_link'/>
  </joint>
  <joint name='camera_sensor_joint' type='fixed'>
    <parent link='base_link'/>
    <child link='camera_link'/>
  </joint>
  <plugin
    filename="libignition-gazebo-diff-drive-system.so"
    name="ignition::gazebo::systems::DiffDrive">
    <left_joint>left_wheel_joint</left_joint>
    <right_joint>right_wheel_joint</right_joint>
    <wheel_separation>0.1182</wheel_separation>
    <wheel_radius>0.04</wheel_radius>
    <odom_publish_frequency>1</odom_publish_frequency>
    <topic>cmd_vel</topic>
  </plugin>
</robot>
